[2025-04-06T10:03:24.544+0000] {local_task_job_runner.py:123} INFO - ::group::Pre task execution logs
[2025-04-06T10:03:24.556+0000] {taskinstance.py:2613} INFO - Dependencies all met for dep_context=non-requeueable deps ti=<TaskInstance: weather_api_dag.get_weather_data manual__2025-04-06T10:03:22.210812+00:00 [queued]>
[2025-04-06T10:03:24.562+0000] {taskinstance.py:2613} INFO - Dependencies all met for dep_context=requeueable deps ti=<TaskInstance: weather_api_dag.get_weather_data manual__2025-04-06T10:03:22.210812+00:00 [queued]>
[2025-04-06T10:03:24.562+0000] {taskinstance.py:2866} INFO - Starting attempt 1 of 1
[2025-04-06T10:03:24.572+0000] {taskinstance.py:2889} INFO - Executing <Task(PythonOperator): get_weather_data> on 2025-04-06 10:03:22.210812+00:00
[2025-04-06T10:03:24.584+0000] {logging_mixin.py:190} WARNING - /home/***/.local/lib/python3.12/site-packages/***/task/task_runner/standard_task_runner.py:70 DeprecationWarning: This process (pid=170941) is multi-threaded, use of fork() may lead to deadlocks in the child.
[2025-04-06T10:03:24.583+0000] {standard_task_runner.py:104} INFO - Running: ['***', 'tasks', 'run', 'weather_api_dag', 'get_weather_data', 'manual__2025-04-06T10:03:22.210812+00:00', '--job-id', '704', '--raw', '--subdir', 'DAGS_FOLDER/weatherAPIDAG.py', '--cfg-path', '/tmp/tmpkog1p360']
[2025-04-06T10:03:24.584+0000] {standard_task_runner.py:105} INFO - Job 704: Subtask get_weather_data
[2025-04-06T10:03:24.584+0000] {standard_task_runner.py:72} INFO - Started process 170947 to run task
[2025-04-06T10:03:24.618+0000] {task_command.py:467} INFO - Running <TaskInstance: weather_api_dag.get_weather_data manual__2025-04-06T10:03:22.210812+00:00 [running]> on host ab13fcc6a433
[2025-04-06T10:03:24.683+0000] {taskinstance.py:3132} INFO - Exporting env vars: AIRFLOW_CTX_DAG_OWNER='***' AIRFLOW_CTX_DAG_ID='weather_api_dag' AIRFLOW_CTX_TASK_ID='get_weather_data' AIRFLOW_CTX_EXECUTION_DATE='2025-04-06T10:03:22.210812+00:00' AIRFLOW_CTX_TRY_NUMBER='1' AIRFLOW_CTX_DAG_RUN_ID='manual__2025-04-06T10:03:22.210812+00:00'
[2025-04-06T10:03:24.685+0000] {logging_mixin.py:190} INFO - Task instance is in running state
[2025-04-06T10:03:24.685+0000] {logging_mixin.py:190} INFO -  Previous state of the Task instance: queued
[2025-04-06T10:03:24.685+0000] {logging_mixin.py:190} INFO - Current task name:get_weather_data state:running start_date:2025-04-06 10:03:24.556626+00:00
[2025-04-06T10:03:24.685+0000] {logging_mixin.py:190} INFO - Dag name:weather_api_dag and current dag run status:running
[2025-04-06T10:03:24.686+0000] {taskinstance.py:731} INFO - ::endgroup::
[2025-04-06T10:03:24.736+0000] {logging_mixin.py:190} INFO - https://api.openweathermap.org/data/2.5/weather?q=bangkok&appid=a721af6b5545eb25497f1edd07d1ee0c&units=metric
[2025-04-06T10:03:24.737+0000] {logging_mixin.py:190} INFO - {'coord': {'lon': 100.5167, 'lat': 13.75}, 'weather': [{'id': 802, 'main': 'Clouds', 'description': 'scattered clouds', 'icon': '03d'}], 'base': 'stations', 'main': {'temp': 36.05, 'feels_like': 41.53, 'temp_min': 34.94, 'temp_max': 36.08, 'pressure': 1007, 'humidity': 46, 'sea_level': 1007, 'grnd_level': 1006}, 'visibility': 10000, 'wind': {'speed': 6.69, 'deg': 189, 'gust': 7.1}, 'clouds': {'all': 28}, 'dt': 1743933388, 'sys': {'type': 2, 'id': 2093772, 'country': 'TH', 'sunrise': 1743894627, 'sunset': 1743938997}, 'timezone': 25200, 'id': 1609350, 'name': 'Bangkok', 'cod': 200}
[2025-04-06T10:03:24.737+0000] {taskinstance.py:3311} ERROR - Task failed with exception
Traceback (most recent call last):
  File "/home/airflow/.local/lib/python3.12/site-packages/airflow/models/taskinstance.py", line 767, in _execute_task
    result = _execute_callable(context=context, **execute_callable_kwargs)
             ^^^^^^^^^^^^^^^^^^^^^^^^^^^^^^^^^^^^^^^^^^^^^^^^^^^^^^^^^^^^^
  File "/home/airflow/.local/lib/python3.12/site-packages/airflow/models/taskinstance.py", line 733, in _execute_callable
    return ExecutionCallableRunner(
           ^^^^^^^^^^^^^^^^^^^^^^^^
  File "/home/airflow/.local/lib/python3.12/site-packages/airflow/utils/operator_helpers.py", line 252, in run
    return self.func(*args, **kwargs)
           ^^^^^^^^^^^^^^^^^^^^^^^^^^
  File "/home/airflow/.local/lib/python3.12/site-packages/airflow/models/baseoperator.py", line 422, in wrapper
    return func(self, *args, **kwargs)
           ^^^^^^^^^^^^^^^^^^^^^^^^^^^
  File "/home/airflow/.local/lib/python3.12/site-packages/airflow/operators/python.py", line 238, in execute
    return_value = self.execute_callable()
                   ^^^^^^^^^^^^^^^^^^^^^^^
  File "/home/airflow/.local/lib/python3.12/site-packages/airflow/operators/python.py", line 256, in execute_callable
    return runner.run(*self.op_args, **self.op_kwargs)
           ^^^^^^^^^^^^^^^^^^^^^^^^^^^^^^^^^^^^^^^^^^^
  File "/home/airflow/.local/lib/python3.12/site-packages/airflow/utils/operator_helpers.py", line 252, in run
    return self.func(*args, **kwargs)
           ^^^^^^^^^^^^^^^^^^^^^^^^^^
  File "/opt/airflow/dags/weatherAPIDAG.py", line 29, in _get_weather_data
    with open ("/opt/airflow/dags/data.json","W") as f:
         ^^^^^^^^^^^^^^^^^^^^^^^^^^^^^^^^^^^^^^^^
ValueError: invalid mode: 'W'
[2025-04-06T10:03:24.745+0000] {logging_mixin.py:190} INFO - Task instance in failure state
[2025-04-06T10:03:24.745+0000] {logging_mixin.py:190} INFO - Task start:2025-04-06 10:03:24.556626+00:00 end:2025-04-06 10:03:24.744806+00:00 duration:0.18818
[2025-04-06T10:03:24.745+0000] {logging_mixin.py:190} INFO - Task:<Task(PythonOperator): get_weather_data> dag:<DAG: weather_api_dag> dagrun:<DagRun weather_api_dag @ 2025-04-06 10:03:22.210812+00:00: manual__2025-04-06T10:03:22.210812+00:00, state:running, queued_at: 2025-04-06 10:03:22.218403+00:00. externally triggered: True>
[2025-04-06T10:03:24.745+0000] {logging_mixin.py:190} INFO - Failure caused by invalid mode: 'W'
[2025-04-06T10:03:24.746+0000] {taskinstance.py:1225} INFO - Marking task as FAILED. dag_id=weather_api_dag, task_id=get_weather_data, run_id=manual__2025-04-06T10:03:22.210812+00:00, execution_date=20250406T100322, start_date=20250406T100324, end_date=20250406T100324
[2025-04-06T10:03:24.754+0000] {taskinstance.py:340} INFO - ::group::Post task execution logs
[2025-04-06T10:03:24.755+0000] {standard_task_runner.py:124} ERROR - Failed to execute job 704 for task get_weather_data (invalid mode: 'W'; 170947)
Traceback (most recent call last):
  File "/home/airflow/.local/lib/python3.12/site-packages/airflow/task/task_runner/standard_task_runner.py", line 117, in _start_by_fork
    ret = args.func(args, dag=self.dag)
          ^^^^^^^^^^^^^^^^^^^^^^^^^^^^^
  File "/home/airflow/.local/lib/python3.12/site-packages/airflow/cli/cli_config.py", line 49, in command
    return func(*args, **kwargs)
           ^^^^^^^^^^^^^^^^^^^^^
  File "/home/airflow/.local/lib/python3.12/site-packages/airflow/utils/cli.py", line 116, in wrapper
    return f(*args, **kwargs)
           ^^^^^^^^^^^^^^^^^^
  File "/home/airflow/.local/lib/python3.12/site-packages/airflow/cli/commands/task_command.py", line 483, in task_run
    task_return_code = _run_task_by_selected_method(args, _dag, ti)
                       ^^^^^^^^^^^^^^^^^^^^^^^^^^^^^^^^^^^^^^^^^^^^
  File "/home/airflow/.local/lib/python3.12/site-packages/airflow/cli/commands/task_command.py", line 256, in _run_task_by_selected_method
    return _run_raw_task(args, ti)
           ^^^^^^^^^^^^^^^^^^^^^^^
  File "/home/airflow/.local/lib/python3.12/site-packages/airflow/cli/commands/task_command.py", line 341, in _run_raw_task
    return ti._run_raw_task(
           ^^^^^^^^^^^^^^^^^
  File "/home/airflow/.local/lib/python3.12/site-packages/airflow/utils/session.py", line 97, in wrapper
    return func(*args, session=session, **kwargs)
           ^^^^^^^^^^^^^^^^^^^^^^^^^^^^^^^^^^^^^^
  File "/home/airflow/.local/lib/python3.12/site-packages/airflow/models/taskinstance.py", line 3005, in _run_raw_task
    return _run_raw_task(
           ^^^^^^^^^^^^^^
  File "/home/airflow/.local/lib/python3.12/site-packages/airflow/models/taskinstance.py", line 273, in _run_raw_task
    TaskInstance._execute_task_with_callbacks(
  File "/home/airflow/.local/lib/python3.12/site-packages/airflow/models/taskinstance.py", line 3159, in _execute_task_with_callbacks
    result = self._execute_task(context, task_orig)
             ^^^^^^^^^^^^^^^^^^^^^^^^^^^^^^^^^^^^^^
  File "/home/airflow/.local/lib/python3.12/site-packages/airflow/models/taskinstance.py", line 3183, in _execute_task
    return _execute_task(self, context, task_orig)
           ^^^^^^^^^^^^^^^^^^^^^^^^^^^^^^^^^^^^^^^
  File "/home/airflow/.local/lib/python3.12/site-packages/airflow/models/taskinstance.py", line 767, in _execute_task
    result = _execute_callable(context=context, **execute_callable_kwargs)
             ^^^^^^^^^^^^^^^^^^^^^^^^^^^^^^^^^^^^^^^^^^^^^^^^^^^^^^^^^^^^^
  File "/home/airflow/.local/lib/python3.12/site-packages/airflow/models/taskinstance.py", line 733, in _execute_callable
    return ExecutionCallableRunner(
           ^^^^^^^^^^^^^^^^^^^^^^^^
  File "/home/airflow/.local/lib/python3.12/site-packages/airflow/utils/operator_helpers.py", line 252, in run
    return self.func(*args, **kwargs)
           ^^^^^^^^^^^^^^^^^^^^^^^^^^
  File "/home/airflow/.local/lib/python3.12/site-packages/airflow/models/baseoperator.py", line 422, in wrapper
    return func(self, *args, **kwargs)
           ^^^^^^^^^^^^^^^^^^^^^^^^^^^
  File "/home/airflow/.local/lib/python3.12/site-packages/airflow/operators/python.py", line 238, in execute
    return_value = self.execute_callable()
                   ^^^^^^^^^^^^^^^^^^^^^^^
  File "/home/airflow/.local/lib/python3.12/site-packages/airflow/operators/python.py", line 256, in execute_callable
    return runner.run(*self.op_args, **self.op_kwargs)
           ^^^^^^^^^^^^^^^^^^^^^^^^^^^^^^^^^^^^^^^^^^^
  File "/home/airflow/.local/lib/python3.12/site-packages/airflow/utils/operator_helpers.py", line 252, in run
    return self.func(*args, **kwargs)
           ^^^^^^^^^^^^^^^^^^^^^^^^^^
  File "/opt/airflow/dags/weatherAPIDAG.py", line 29, in _get_weather_data
    with open ("/opt/airflow/dags/data.json","W") as f:
         ^^^^^^^^^^^^^^^^^^^^^^^^^^^^^^^^^^^^^^^^
ValueError: invalid mode: 'W'
[2025-04-06T10:03:24.800+0000] {local_task_job_runner.py:266} INFO - Task exited with return code 1
[2025-04-06T10:03:24.817+0000] {taskinstance.py:3895} INFO - 0 downstream tasks scheduled from follow-on schedule check
[2025-04-06T10:03:24.820+0000] {local_task_job_runner.py:245} INFO - ::endgroup::
