[2025-04-06T08:00:53.849+0000] {local_task_job_runner.py:123} INFO - ::group::Pre task execution logs
[2025-04-06T08:00:53.862+0000] {taskinstance.py:2613} INFO - Dependencies all met for dep_context=non-requeueable deps ti=<TaskInstance: play_with_airflow_connections_and_hooks.get_data scheduled__2025-04-05T00:00:00+00:00 [queued]>
[2025-04-06T08:00:53.871+0000] {taskinstance.py:2613} INFO - Dependencies all met for dep_context=requeueable deps ti=<TaskInstance: play_with_airflow_connections_and_hooks.get_data scheduled__2025-04-05T00:00:00+00:00 [queued]>
[2025-04-06T08:00:53.872+0000] {taskinstance.py:2866} INFO - Starting attempt 1 of 1
[2025-04-06T08:00:53.889+0000] {taskinstance.py:2889} INFO - Executing <Task(PythonOperator): get_data> on 2025-04-05 00:00:00+00:00
[2025-04-06T08:00:53.904+0000] {standard_task_runner.py:104} INFO - Running: ['***', 'tasks', 'run', 'play_with_***_connections_and_hooks', 'get_data', 'scheduled__2025-04-05T00:00:00+00:00', '--job-id', '694', '--raw', '--subdir', 'DAGS_FOLDER/play_with_***_connections_and_hooks.py', '--cfg-path', '/tmp/tmpjvlbc2wx']
[2025-04-06T08:00:53.905+0000] {standard_task_runner.py:105} INFO - Job 694: Subtask get_data
[2025-04-06T08:00:53.907+0000] {logging_mixin.py:190} WARNING - /home/***/.local/lib/python3.12/site-packages/***/task/task_runner/standard_task_runner.py:70 DeprecationWarning: This process (pid=97099) is multi-threaded, use of fork() may lead to deadlocks in the child.
[2025-04-06T08:00:53.908+0000] {standard_task_runner.py:72} INFO - Started process 97115 to run task
[2025-04-06T08:00:53.989+0000] {task_command.py:467} INFO - Running <TaskInstance: play_with_airflow_connections_and_hooks.get_data scheduled__2025-04-05T00:00:00+00:00 [running]> on host ab13fcc6a433
[2025-04-06T08:00:54.089+0000] {taskinstance.py:3132} INFO - Exporting env vars: AIRFLOW_CTX_DAG_OWNER='***' AIRFLOW_CTX_DAG_ID='play_with_***_connections_and_hooks' AIRFLOW_CTX_TASK_ID='get_data' AIRFLOW_CTX_EXECUTION_DATE='2025-04-05T00:00:00+00:00' AIRFLOW_CTX_TRY_NUMBER='1' AIRFLOW_CTX_DAG_RUN_ID='scheduled__2025-04-05T00:00:00+00:00'
[2025-04-06T08:00:54.090+0000] {logging_mixin.py:190} INFO - Task instance is in running state
[2025-04-06T08:00:54.090+0000] {logging_mixin.py:190} INFO -  Previous state of the Task instance: queued
[2025-04-06T08:00:54.091+0000] {logging_mixin.py:190} INFO - Current task name:get_data state:running start_date:2025-04-06 08:00:53.862471+00:00
[2025-04-06T08:00:54.092+0000] {logging_mixin.py:190} INFO - Dag name:play_with_***_connections_and_hooks and current dag run status:running
[2025-04-06T08:00:54.092+0000] {taskinstance.py:731} INFO - ::endgroup::
[2025-04-06T08:00:54.125+0000] {taskinstance.py:3311} ERROR - Task failed with exception
Traceback (most recent call last):
  File "/home/airflow/.local/lib/python3.12/site-packages/airflow/models/taskinstance.py", line 767, in _execute_task
    result = _execute_callable(context=context, **execute_callable_kwargs)
             ^^^^^^^^^^^^^^^^^^^^^^^^^^^^^^^^^^^^^^^^^^^^^^^^^^^^^^^^^^^^^
  File "/home/airflow/.local/lib/python3.12/site-packages/airflow/models/taskinstance.py", line 733, in _execute_callable
    return ExecutionCallableRunner(
           ^^^^^^^^^^^^^^^^^^^^^^^^
  File "/home/airflow/.local/lib/python3.12/site-packages/airflow/utils/operator_helpers.py", line 252, in run
    return self.func(*args, **kwargs)
           ^^^^^^^^^^^^^^^^^^^^^^^^^^
  File "/home/airflow/.local/lib/python3.12/site-packages/airflow/models/baseoperator.py", line 422, in wrapper
    return func(self, *args, **kwargs)
           ^^^^^^^^^^^^^^^^^^^^^^^^^^^
  File "/home/airflow/.local/lib/python3.12/site-packages/airflow/operators/python.py", line 238, in execute
    return_value = self.execute_callable()
                   ^^^^^^^^^^^^^^^^^^^^^^^
  File "/home/airflow/.local/lib/python3.12/site-packages/airflow/operators/python.py", line 256, in execute_callable
    return runner.run(*self.op_args, **self.op_kwargs)
           ^^^^^^^^^^^^^^^^^^^^^^^^^^^^^^^^^^^^^^^^^^^
  File "/home/airflow/.local/lib/python3.12/site-packages/airflow/utils/operator_helpers.py", line 252, in run
    return self.func(*args, **kwargs)
           ^^^^^^^^^^^^^^^^^^^^^^^^^^
  File "/opt/airflow/dags/play_with_airflow_connections_and_hooks.py", line 12, in _get_data
    connection = pg_hook.get_conn()
                 ^^^^^^^^^^^^^^^^^^
  File "/home/airflow/.local/lib/python3.12/site-packages/airflow/providers/postgres/hooks/postgres.py", line 157, in get_conn
    conn = deepcopy(self.connection)
                    ^^^^^^^^^^^^^^^
  File "/home/airflow/.local/lib/python3.12/site-packages/airflow/providers/common/sql/hooks/sql.py", line 212, in connection
    self._connection = self.get_connection(self.get_conn_id())
                       ^^^^^^^^^^^^^^^^^^^^^^^^^^^^^^^^^^^^^^^
  File "/home/airflow/.local/lib/python3.12/site-packages/airflow/hooks/base.py", line 83, in get_connection
    conn = Connection.get_connection_from_secrets(conn_id)
           ^^^^^^^^^^^^^^^^^^^^^^^^^^^^^^^^^^^^^^^^^^^^^^^
  File "/home/airflow/.local/lib/python3.12/site-packages/airflow/models/connection.py", line 537, in get_connection_from_secrets
    raise AirflowNotFoundException(f"The conn_id `{conn_id}` isn't defined")
airflow.exceptions.AirflowNotFoundException: The conn_id `my_postgres_conn` isn't defined
[2025-04-06T08:00:54.146+0000] {logging_mixin.py:190} INFO - Task instance in failure state
[2025-04-06T08:00:54.146+0000] {logging_mixin.py:190} INFO - Task start:2025-04-06 08:00:53.862471+00:00 end:2025-04-06 08:00:54.145813+00:00 duration:0.283342
[2025-04-06T08:00:54.147+0000] {logging_mixin.py:190} INFO - Task:<Task(PythonOperator): get_data> dag:<DAG: play_with_***_connections_and_hooks> dagrun:<DagRun play_with_***_connections_and_hooks @ 2025-04-05 00:00:00+00:00: scheduled__2025-04-05T00:00:00+00:00, state:running, queued_at: 2025-04-06 08:00:52.536685+00:00. externally triggered: False>
[2025-04-06T08:00:54.147+0000] {logging_mixin.py:190} INFO - Failure caused by The conn_id `my_postgres_conn` isn't defined
[2025-04-06T08:00:54.147+0000] {taskinstance.py:1225} INFO - Marking task as FAILED. dag_id=play_with_***_connections_and_hooks, task_id=get_data, run_id=scheduled__2025-04-05T00:00:00+00:00, execution_date=20250405T000000, start_date=20250406T080053, end_date=20250406T080054
[2025-04-06T08:00:54.159+0000] {taskinstance.py:340} INFO - ::group::Post task execution logs
[2025-04-06T08:00:54.160+0000] {standard_task_runner.py:124} ERROR - Failed to execute job 694 for task get_data (The conn_id `my_postgres_conn` isn't defined; 97115)
Traceback (most recent call last):
  File "/home/airflow/.local/lib/python3.12/site-packages/airflow/task/task_runner/standard_task_runner.py", line 117, in _start_by_fork
    ret = args.func(args, dag=self.dag)
          ^^^^^^^^^^^^^^^^^^^^^^^^^^^^^
  File "/home/airflow/.local/lib/python3.12/site-packages/airflow/cli/cli_config.py", line 49, in command
    return func(*args, **kwargs)
           ^^^^^^^^^^^^^^^^^^^^^
  File "/home/airflow/.local/lib/python3.12/site-packages/airflow/utils/cli.py", line 116, in wrapper
    return f(*args, **kwargs)
           ^^^^^^^^^^^^^^^^^^
  File "/home/airflow/.local/lib/python3.12/site-packages/airflow/cli/commands/task_command.py", line 483, in task_run
    task_return_code = _run_task_by_selected_method(args, _dag, ti)
                       ^^^^^^^^^^^^^^^^^^^^^^^^^^^^^^^^^^^^^^^^^^^^
  File "/home/airflow/.local/lib/python3.12/site-packages/airflow/cli/commands/task_command.py", line 256, in _run_task_by_selected_method
    return _run_raw_task(args, ti)
           ^^^^^^^^^^^^^^^^^^^^^^^
  File "/home/airflow/.local/lib/python3.12/site-packages/airflow/cli/commands/task_command.py", line 341, in _run_raw_task
    return ti._run_raw_task(
           ^^^^^^^^^^^^^^^^^
  File "/home/airflow/.local/lib/python3.12/site-packages/airflow/utils/session.py", line 97, in wrapper
    return func(*args, session=session, **kwargs)
           ^^^^^^^^^^^^^^^^^^^^^^^^^^^^^^^^^^^^^^
  File "/home/airflow/.local/lib/python3.12/site-packages/airflow/models/taskinstance.py", line 3005, in _run_raw_task
    return _run_raw_task(
           ^^^^^^^^^^^^^^
  File "/home/airflow/.local/lib/python3.12/site-packages/airflow/models/taskinstance.py", line 273, in _run_raw_task
    TaskInstance._execute_task_with_callbacks(
  File "/home/airflow/.local/lib/python3.12/site-packages/airflow/models/taskinstance.py", line 3159, in _execute_task_with_callbacks
    result = self._execute_task(context, task_orig)
             ^^^^^^^^^^^^^^^^^^^^^^^^^^^^^^^^^^^^^^
  File "/home/airflow/.local/lib/python3.12/site-packages/airflow/models/taskinstance.py", line 3183, in _execute_task
    return _execute_task(self, context, task_orig)
           ^^^^^^^^^^^^^^^^^^^^^^^^^^^^^^^^^^^^^^^
  File "/home/airflow/.local/lib/python3.12/site-packages/airflow/models/taskinstance.py", line 767, in _execute_task
    result = _execute_callable(context=context, **execute_callable_kwargs)
             ^^^^^^^^^^^^^^^^^^^^^^^^^^^^^^^^^^^^^^^^^^^^^^^^^^^^^^^^^^^^^
  File "/home/airflow/.local/lib/python3.12/site-packages/airflow/models/taskinstance.py", line 733, in _execute_callable
    return ExecutionCallableRunner(
           ^^^^^^^^^^^^^^^^^^^^^^^^
  File "/home/airflow/.local/lib/python3.12/site-packages/airflow/utils/operator_helpers.py", line 252, in run
    return self.func(*args, **kwargs)
           ^^^^^^^^^^^^^^^^^^^^^^^^^^
  File "/home/airflow/.local/lib/python3.12/site-packages/airflow/models/baseoperator.py", line 422, in wrapper
    return func(self, *args, **kwargs)
           ^^^^^^^^^^^^^^^^^^^^^^^^^^^
  File "/home/airflow/.local/lib/python3.12/site-packages/airflow/operators/python.py", line 238, in execute
    return_value = self.execute_callable()
                   ^^^^^^^^^^^^^^^^^^^^^^^
  File "/home/airflow/.local/lib/python3.12/site-packages/airflow/operators/python.py", line 256, in execute_callable
    return runner.run(*self.op_args, **self.op_kwargs)
           ^^^^^^^^^^^^^^^^^^^^^^^^^^^^^^^^^^^^^^^^^^^
  File "/home/airflow/.local/lib/python3.12/site-packages/airflow/utils/operator_helpers.py", line 252, in run
    return self.func(*args, **kwargs)
           ^^^^^^^^^^^^^^^^^^^^^^^^^^
  File "/opt/airflow/dags/play_with_airflow_connections_and_hooks.py", line 12, in _get_data
    connection = pg_hook.get_conn()
                 ^^^^^^^^^^^^^^^^^^
  File "/home/airflow/.local/lib/python3.12/site-packages/airflow/providers/postgres/hooks/postgres.py", line 157, in get_conn
    conn = deepcopy(self.connection)
                    ^^^^^^^^^^^^^^^
  File "/home/airflow/.local/lib/python3.12/site-packages/airflow/providers/common/sql/hooks/sql.py", line 212, in connection
    self._connection = self.get_connection(self.get_conn_id())
                       ^^^^^^^^^^^^^^^^^^^^^^^^^^^^^^^^^^^^^^^
  File "/home/airflow/.local/lib/python3.12/site-packages/airflow/hooks/base.py", line 83, in get_connection
    conn = Connection.get_connection_from_secrets(conn_id)
           ^^^^^^^^^^^^^^^^^^^^^^^^^^^^^^^^^^^^^^^^^^^^^^^
  File "/home/airflow/.local/lib/python3.12/site-packages/airflow/models/connection.py", line 537, in get_connection_from_secrets
    raise AirflowNotFoundException(f"The conn_id `{conn_id}` isn't defined")
airflow.exceptions.AirflowNotFoundException: The conn_id `my_postgres_conn` isn't defined
[2025-04-06T08:00:54.216+0000] {local_task_job_runner.py:266} INFO - Task exited with return code 1
[2025-04-06T08:00:54.230+0000] {taskinstance.py:3895} INFO - 0 downstream tasks scheduled from follow-on schedule check
[2025-04-06T08:00:54.231+0000] {local_task_job_runner.py:245} INFO - ::endgroup::
